<?xml version="1.0" ?>
<!-- =================================================================================== -->
<!-- |    This document was autogenerated by xacro from arm.urdf.xacro                 | -->
<!-- |    EDITING THIS FILE BY HAND IS NOT RECOMMENDED                                 | -->
<!-- =================================================================================== -->
<robot name="arm">
  <link name="arm_a1">
    <inertial>
      <mass value="1.733599"/>
      <origin rpy="0 0 0" xyz="-0.085057488 -7.874e-06 -0.19600748199999998"/>
      <inertia ixx="70910.68402480001" ixy="-54.50901710000001" ixz="-1641.1270861" iyy="48858.5770933" iyz="-2.6435432000000003" izz="28334.269394600004"/>
    </inertial>
  </link>
  <joint name="arm_j1" type="revolute">
    <origin rpy="0 0 0" xyz="-0.08889999999999999 0.0 0.013134974999999998"/>
    <parent link="arm_a1"/>
    <child link="arm_a2"/>
    <axis xyz="0 0 1"/>
    <limit effort="0" lower="-3.141592653589793" upper="3.141592653589793" velocity="0"/>
  </joint>
  <link name="arm_a2">
    <inertial>
      <mass value="1.6581896"/>
      <origin rpy="0 0 0" xyz="0.0 -0.0009649460000000001 0.06909562"/>
      <inertia ixx="15137.097100000003" ixy="0.0" ixz="0.0" iyy="10260.60358" iyz="100.4476109" izz="7660.6507200000015"/>
    </inertial>
  </link>
  <joint name="arm_j2" type="revolute">
    <origin rpy="0 0 0" xyz="0.0 0.0 0.09525"/>
    <parent link="arm_a2"/>
    <child link="arm_a3"/>
    <axis xyz="0 1 0"/>
    <limit effort="0" lower="-2.356194490192345" upper="0.2617993877991494" velocity="0"/>
  </joint>
  <link name="arm_a3">
    <inertial>
      <mass value="2.9794204"/>
      <origin rpy="0 0 0" xyz="0.22864571999999997 -0.11213084 -9.397999999999999e-06"/>
      <inertia ixx="46091.86306000001" ixy="17.3798904" ixz="108.75789830000001" iyy="327229.8701" iyz="-3.4731658000000003" izz="369329.7017"/>
    </inertial>
  </link>
  <joint name="arm_j3" type="revolute">
    <origin rpy="0 0 0" xyz="0.4572 0.0 0.0"/>
    <parent link="arm_a3"/>
    <child link="arm_a4"/>
    <axis xyz="0 1 0"/>
    <limit effort="0" lower="-2.0943951023931953" upper="2.0943951023931953" velocity="0"/>
  </joint>
  <link name="arm_a4">
    <inertial>
      <mass value="2.4176862000000003"/>
      <origin rpy="0 0 0" xyz="0.12940538 -0.00062992 1.016e-05"/>
      <inertia ixx="12552.611780000001" ixy="-511.58185480000003" ixz="0.4007499" iyy="164701.1782" iyz="-0.07733770000000001" izz="173770.7812"/>
    </inertial>
  </link>
  <joint name="arm_j4" type="continuous">
    <origin rpy="0 0 0" xyz="0.113949999938 0.0 0.0"/>
    <parent link="arm_a4"/>
    <child link="arm_a5"/>
    <axis xyz="1 0 0"/>
    <limit effort="0" velocity="0"/>
  </joint>
  <link name="arm_a5">
    <inertial>
      <mass value="605.1366"/>
      <origin rpy="0 0 0" xyz="9.558527999999999 -0.16051784 -2.8701999999999997e-05"/>
      <inertia ixx="4068455169.0000005" ixy="365990119.20000005" ixz="366826.7725" iyy="6311881232.0" iyz="-197893.11290000004" izz="8997889860.0"/>
    </inertial>
  </link>
  <joint name="arm_j5" type="revolute">
    <origin rpy="0 0 0" xyz="0.43815 0.0 0.0"/>
    <parent link="arm_a5"/>
    <child link="arm_a6"/>
    <axis xyz="0 1 0"/>
    <limit effort="0" lower="-1.5707963267948966" upper="1.5707963267948966" velocity="0"/>
  </joint>
  <link name="arm_a6">
    <inertial>
      <mass value="1.0315788000000001"/>
      <origin rpy="0 0 0" xyz="0.04199382 2.54e-05 4.826e-06"/>
      <inertia ixx="5757.791765000001" ixy="1.9896881000000002" ixz="0.05624560000000001" iyy="4469.626911" iyz="-0.5202718000000001" izz="6246.5660290000005"/>
    </inertial>
  </link>
  <joint name="arm_j6" type="continuous">
    <origin rpy="0 0 0" xyz="0.075849999938 0.0 0.0"/>
    <parent link="arm_a6"/>
    <child link="arm_a7"/>
    <axis xyz="1 0 0"/>
    <limit effort="0" velocity="0"/>
  </joint>
  <link name="arm_a7">
    <!-- Waiting for the part to be finished -->
  </link>
</robot>
